Workbook
Name Slicer_Month: #N/A
Name Slicer_Product: #N/A

Sheet FY Summary 2026-27
A1: SUMMARY — JANUARY 2026 TO JUNE 2026
A2: Month | B2: Opening Stock | C2: Total Production | D2: Total Sales | E2: Closing Stock
A3: January 2026 | B3: =IFERROR('Jan 2026'!D379,"") -> 4010 | C3: =IFERROR('Jan 2026'!E379,"") -> 30914 | D3: =IFERROR('Jan 2026'!F379,"") -> 23350 | E3: =IFERROR('Jan 2026'!G379,"") -> 11574
A4: February 2026 | B4: =IFERROR('Feb 2026'!D343,"") -> 11574 | C4: =IFERROR('Feb 2026'!E343,"") -> 28180 | D4: =IFERROR('Feb 2026'!F343,"") -> 21337 | E4: =IFERROR('Feb 2026'!G343,"") -> 18417
A5: March 2026 | B5: =IFERROR('Mar 2026'!D379,"") -> 18417 | C5: =IFERROR('Mar 2026'!E379,"") -> 30864 | D5: =IFERROR('Mar 2026'!F379,"") -> 23560 | E5: =IFERROR('Mar 2026'!G379,"") -> 25721
A6: April 2026 | B6: =IFERROR('Apr 2026'!D367,"") -> 25721 | C6: =IFERROR('Apr 2026'!E367,"") -> 30277 | D6: =IFERROR('Apr 2026'!F367,"") -> 22827 | E6: =IFERROR('Apr 2026'!G367,"") -> 33171
A7: May 2026 | B7: =IFERROR('May 2026'!D379,"") -> 33171 | C7: =IFERROR('May 2026'!E379,"") -> 30492 | D7: =IFERROR('May 2026'!F379,"") -> 23255 | E7: =IFERROR('May 2026'!G379,"") -> 40408
A8: June 2026 | B8: =IFERROR('Jun 2026'!D367,"") -> 40408 | C8: =IFERROR('Jun 2026'!E367,"") -> 30565 | D8: =IFERROR('Jun 2026'!F367,"") -> 23338 | E8: =IFERROR('Jun 2026'!G367,"") -> 47635
A9: TOTAL — Jan to Jun 2026 | B9: =B3 -> 4010 | C9: =SUM(C3:C8) -> 181292 | D9: =SUM(D3:D8) -> 137667 | E9: =E8 -> 47635

Sheet PIVOT
A1: PRODUCTION,SALES AND INVENTORY DASHBOARD
FK2: Sum of Sales | FN2: Month | FO2: Sum of Sales
FK3: 137667 | FN3: April 2026 | FO3: 22827
FN4: February 2026 | FO4: 21337
FK5: Sum of Production | FN5: January 2026 | FO5: 23350
A6: TOTAL SALES(in bags) | D6: TOTAL PRODUCTION(in bags) | G6: BEST MONTH | J6: BEST SELLING PRODUCT | M6: AVG EFFICINECY % | FK6: 181292 | FN6: June 2026 | FO6: 23338
FN7: March 2026 | FO7: 23560
A8: =FK3 -> 137667 | D8: =FK6 -> 181292 | G8: =FN11 -> March 2026 (23560 Bags) | J8: =FN27 -> 50/150# (14990 Bags) | M8: =FK9 -> 76.629382 | FA8: Month | FB8: (All) | FK8: Average of Efficiency % | FN8: May 2026 | FO8: 23255
FK9: 76.629382 | FN9: Grand Total | FO9: 137667
FA10: Product | FB10: Sum of Production | FC10: Sum of Sales
FA11: -100# | FB11: 12422 | FC11: 9668 | FN11: =_xlfn.XLOOKUP(MAX(FO3:FO8),FO3:FO8,FN3:FN8)&" ("& MAX(FO3:FO8)&" Bags)" -> March 2026 (23560 Bags)
FA12: 14/30# | FB12: 17548 | FC12: 12934
FA13: 16/30# | FB13: 15432 | FC13: 12156 | FN13: Product | FO13: Sum of Sales | FQ13: Month | FR13: Max of Closing Stock
FA14: 1mm | FB14: 14308 | FC14: 10665 | FN14: -100# | FO14: 9668 | FQ14: April 2026 | FR14: 4514
FA15: 24/60# | FB15: 18766 | FC15: 12996 | FN15: 14/30# | FO15: 12934 | FQ15: February 2026 | FR15: 2440
FA16: 2mm | FB16: 18545 | FC16: 13668 | FN16: 16/30# | FO16: 12156 | FQ16: January 2026 | FR16: 1529
FA17: 30/80# | FB17: 13725 | FC17: 11657 | FN17: 1mm | FO17: 10665 | FQ17: June 2026 | FR17: 6487
FA18: 3mm | FB18: 12285 | FC18: 10712 | FN18: 24/60# | FO18: 12996 | FQ18: March 2026 | FR18: 3400
FA19: 50/150# | FB19: 20959 | FC19: 14990 | FN19: 2mm | FO19: 13668 | FQ19: May 2026 | FR19: 5454
FA20: 5mm | FB20: 16542 | FC20: 13498 | FN20: 30/80# | FO20: 11657 | FQ20: Grand Total | FR20: 6487
FA21: Dust/150# | FB21: 20760 | FC21: 14723 | FN21: 3mm | FO21: 10712
FA22: Grand Total | FB22: 181292 | FC22: 137667 | FN22: 50/150# | FO22: 14990
FN23: 5mm | FO23: 13498
FN24: Dust/150# | FO24: 14723
FA25: Product | FB25: Average of Efficiency % | FN25: Grand Total | FO25: 137667
FA26: 3mm | FB26: 86.660773
FA27: 30/80# | FB27: 84.771823 | FD27: Product | FE27: Sum of Sales | FN27: =_xlfn.XLOOKUP(MAX(FO14:FO24),FO14:FO24,FN14:FN24)&" ("& MAX(FO14:FO24)&" Bags)" -> 50/150# (14990 Bags)
FA28: 5mm | FB28: 81.559116 | FD28: 50/150# | FE28: 14990 | FJ28: Product | FK28: Sum of Production
FA29: 16/30# | FB29: 78.917127 | FD29: Dust/150# | FE29: 14723 | FJ29: 50/150# | FK29: 20959
FA30: -100# | FB30: 77.440331 | FD30: 2mm | FE30: 13668 | FJ30: Dust/150# | FK30: 20760
FA31: 1mm | FB31: 74.641989 | FD31: 5mm | FE31: 13498 | FJ31: 24/60# | FK31: 18766
FA32: 14/30# | FB32: 73.669613 | FD32: 24/60# | FE32: 12996 | FJ32: 2mm | FK32: 18545
FA33: 2mm | FB33: 73.610497 | FD33: 14/30# | FE33: 12934 | FJ33: 14/30# | FK33: 17548
FA34: 50/150# | FB34: 71.423757 | FD34: 16/30# | FE34: 12156 | FJ34: 5mm | FK34: 16542
FA35: Dust/150# | FB35: 70.900552 | FD35: 30/80# | FE35: 11657 | FJ35: 16/30# | FK35: 15432
FA36: 24/60# | FB36: 69.327624 | FD36: 3mm | FE36: 10712 | FJ36: 1mm | FK36: 14308
DH37: hb | FA37: Grand Total | FB37: 76.629382 | FD37: 1mm | FE37: 10665 | FJ37: 30/80# | FK37: 13725
FD38: -100# | FE38: 9668 | FJ38: -100# | FK38: 12422
FD39: Grand Total | FE39: 137667 | FJ39: 3mm | FK39: 12285
FJ40: Grand Total | FK40: 181292

Sheet Data
A1: PRECIOUS MINERALS — FLAT DATA TABLE | Jan 2026 to Jun 2026 | 11 Products | 1,991 Rows
A2: Month | B2: Date | C2: Day | D2: Weekday/Weekend | E2: Product | F2: Opening Stock | G2: Production | H2: Sales | I2: Closing Stock | J2: Efficiency %
A3: January 2026 | B3: 46023 | C3: Thu | D3: Weekday | E3: 14/30# | F3: 480 | G3: 86 | H3: 63 | I3: 503 | J3: 73.3
A4: January 2026 | B4: 46023 | C4: Thu | D4: Weekday | E4: 16/30# | F4: 380 | G4: 75 | H4: 65 | I4: 390 | J4: 86.7
A5: January 2026 | B5: 46023 | C5: Thu | D5: Weekday | E5: 24/60# | F5: 330 | G5: 124 | H5: 77 | I5: 377 | J5: 62.1
A6: January 2026 | B6: 46023 | C6: Thu | D6: Weekday | E6: 30/80# | F6: 430 | G6: 113 | H6: 85 | I6: 458 | J6: 75.2
A7: January 2026 | B7: 46023 | C7: Thu | D7: Weekday | E7: 50/150# | F7: 280 | G7: 148 | H7: 108 | I7: 320 | J7: 73
A8: January 2026 | B8: 46023 | C8: Thu | D8: Weekday | E8: -100# | F8: 360 | G8: 85 | H8: 67 | I8: 378 | J8: 78.8
A9: January 2026 | B9: 46023 | C9: Thu | D9: Weekday | E9: 5mm | F9: 400 | G9: 118 | H9: 85 | I9: 433 | J9: 72
A10: January 2026 | B10: 46023 | C10: Thu | D10: Weekday | E10: 1mm | F10: 340 | G10: 75 | H10: 53 | I10: 362 | J10: 70.7
A11: January 2026 | B11: 46023 | C11: Thu | D11: Weekday | E11: 2mm | F11: 290 | G11: 128 | H11: 98 | I11: 320 | J11: 76.6
A12: January 2026 | B12: 46023 | C12: Thu | D12: Weekday | E12: 3mm | F12: 270 | G12: 76 | H12: 66 | I12: 280 | J12: 86.8
A13: January 2026 | B13: 46023 | C13: Thu | D13: Weekday | E13: Dust/150# | F13: 450 | G13: 115 | H13: 70 | I13: 495 | J13: 60.9
A14: January 2026 | B14: 46024 | C14: Fri | D14: Weekday | E14: 14/30# | F14: 503 | G14: 137 | H14: 92 | I14: 548 | J14: 67.2
... A1993: June 2026 | B1993: 46203 | C1993: Tue | D1993: Weekday | E1993: Dust/150# | F1993: 6435 | G1993: 166 | H1993: 114 | I1993: 6487 | J1993: 68.7

Sheet Jan 2026
A1: PRECIOUS MINERALS
A5: DAILY PRODUCTION AND DISPATCH REGISTER — JANUARY 2026
A6: Date | B6: Day | C6: Product | D6: Opening stock (in bags) | E6: Production (in bags) | F6: Sales (in bags) | G6: Closing stock (auto)
A7: 46023 | B7: Thu | C7: 14/30# | D7: 480 | E7: 86 | F7: 63 | G7: =IFERROR(D7+E7-F7,"") -> 503
C8: 16/30# | D8: 380 | E8: 75 | F8: 65 | G8: =IFERROR(D8+E8-F8,"") -> 390
C9: 24/60# | D9: 330 | E9: 124 | F9: 77 | G9: =IFERROR(D9+E9-F9,"") -> 377
C10: 30/80# | D10: 430 | E10: 113 | F10: 85 | G10: =IFERROR(D10+E10-F10,"") -> 458
C11: 50/150# | D11: 280 | E11: 148 | F11: 108 | G11: =IFERROR(D11+E11-F11,"") -> 320
C12: -100# | D12: 360 | E12: 85 | F12: 67 | G12: =IFERROR(D12+E12-F12,"") -> 378
C13: 5mm | D13: 400 | E13: 118 | F13: 85 | G13: =IFERROR(D13+E13-F13,"") -> 433
C14: 1mm | D14: 340 | E14: 75 | F14: 53 | G14: =IFERROR(D14+E14-F14,"") -> 362
C15: 2mm | D15: 290 | E15: 128 | F15: 98 | G15: =IFERROR(D15+E15-F15,"") -> 320
C16: 3mm | D16: 270 | E16: 76 | F16: 66 | G16: =IFERROR(D16+E16-F16,"") -> 280
C17: Dust/150# | D17: 450 | E17: 115 | F17: 70 | G17: =IFERROR(D17+E17-F17,"") -> 495
A18: Total — 01 Jan 2026 | D18: =IFERROR(SUM(D7:D17),"") -> 4010 | E18: =IFERROR(SUM(E7:E17),"") -> 1143 | F18: =IFERROR(SUM(F7:F17),"") -> 837 | G18: =IFERROR(SUM(G7:G17),"") -> 4316
A19: 46024 | B19: Fri | C19: 14/30# | D19: =G7 -> 503 | E19: 137 | F19: 92 | G19: =IFERROR(D19+E19-F19,"") -> 548
C20: 16/30# | D20: =G8 -> 390 | E20: 127 | F20: 89 | G20: =IFERROR(D20+E20-F20,"") -> 428
C21: 24/60# | D21: =G9 -> 377 | E21: 101 | F21: 64 | G21: =IFERROR(D21+E21-F21,"") -> 414
C22: 30/80# | D22: =G10 -> 458 | E22: 68 | F22: 63 | G22: =IFERROR(D22+E22-F22,"") -> 463
C23: 50/150# | D23: =G11 -> 320 | E23: 102 | F23: 72 | G23: =IFERROR(D23+E23-F23,"") -> 350
C24: -100# | D24: =G12 -> 378 | E24: 108 | F24: 86 | G24: =IFERROR(D24+E24-F24,"") -> 400
C25: 5mm | D25: =G13 -> 433 | E25: 136 | F25: 105 | G25: =IFERROR(D25+E25-F25,"") -> 464
C26: 1mm | D26: =G14 -> 362 | E26: 95 | F26: 63 | G26: =IFERROR(D26+E26-F26,"") -> 394
C27: 2mm | D27: =G15 -> 320 | E27: 124 | F27: 89 | G27: =IFERROR(D27+E27-F27,"") -> 355
C28: 3mm | D28: =G16 -> 280 | E28: 88 | F28: 83 | G28: =IFERROR(D28+E28-F28,"") -> 285
C29: Dust/150# | D29: =G17 -> 495 | E29: 121 | F29: 92 | G29: =IFERROR(D29+E29-F29,"") -> 524
A30: Total — 02 Jan 2026 | D30: =IFERROR(SUM(D19:D29),"") -> 4316 | E30: =IFERROR(SUM(E19:E29),"") -> 1207 | F30: =IFERROR(SUM(F19:F29),"") -> 898 | G30: =IFERROR(SUM(G19:G29),"") -> 4625
A31: 46025 | B31: Sat | C31: 14/30# | D31: =G19 -> 548 | E31: 66 | F31: 52 | G31: =IFERROR(D31+E31-F31,"") -> 562
C32: 16/30# | D32: =G20 -> 428 | E32: 59 | F32: 49 | G32: =IFERROR(D32+E32-F32,"") -> 438
C33: 24/60# | D33: =G21 -> 414 | E33: 78 | F33: 59 | G33: =IFERROR(D33+E33-F33,"") -> 433
C34: 30/80# | D34: =G22 -> 463 | E34: 47 | F34: 43 | G34: =IFERROR(D34+E34-F34,"") -> 467
C35: 50/150# | D35: =G23 -> 350 | E35: 42 | F35: 28 | G35: =IFERROR(D35+E35-F35,"") -> 364
C36: -100# | D36: =G24 -> 400 | E36: 25 | F36: 20 | G36: =IFERROR(D36+E36-F36,"") -> 405
C37: 5mm | D37: =G25 -> 464 | E37: 46 | F37: 35 | G37: =IFERROR(D37+E37-F37,"") -> 475
C38: 1mm | D38: =G26 -> 394 | E38: 47 | F38: 36 | G38: =IFERROR(D38+E38-F38,"") -> 405
C39: 2mm | D39: =G27 -> 355 | E39: 69 | F39: 50 | G39: =IFERROR(D39+E39-F39,"") -> 374
C40: 3mm | D40: =G28 -> 285 | E40: 50 | F40: 40 | G40: =IFERROR(D40+E40-F40,"") -> 295
C41: Dust/150# | D41: =G29 -> 524 | E41: 84 | F41: 65 | G41: =IFERROR(D41+E41-F41,"") -> 543
A42: Total — 03 Jan 2026 | D42: =IFERROR(SUM(D31:D41),"") -> 4625 | E42: =IFERROR(SUM(E31:E41),"") -> 613 | F42: =IFERROR(SUM(F31:F41),"") -> 477 | G42: =IFERROR(SUM(G31:G41),"") -> 4761
A43: 46026 | B43: Sun | C43: 14/30# | D43: =G31 -> 562 | E43: 32 | F43: 25 | G43: =IFERROR(D43+E43-F43,"") -> 569
...

Sheet Feb 2026
A1: PRECIOUS MINERALS
A5: DAILY PRODUCTION AND DISPATCH REGISTER — FEBRUARY 2026
A6: Date | B6: Day | C6: Product | D6: Opening stock (in bags) | E6: Production (in bags) | F6: Sales (in bags) | G6: Closing stock (auto)
A7: 46054 | B7: Sun | C7: 14/30# | D7: ='Jan 2026'!G367 -> 1264 | E7: 50 | F7: 34 | G7: =IFERROR(D7+E7-F7,"") -> 1280
C8: 16/30# | D8: ='Jan 2026'!G368 -> 914 | E8: 48 | F8: 42 | G8: =IFERROR(D8+E8-F8,"") -> 920
C9: 24/60# | D9: ='Jan 2026'!G369 -> 1310 | E9: 66 | F9: 44 | G9: =IFERROR(D9+E9-F9,"") -> 1332
C10: 30/80# | D10: ='Jan 2026'!G370 -> 792 | E10: 38 | F10: 36 | G10: =IFERROR(D10+E10-F10,"") -> 794
C11: 50/150# | D11: ='Jan 2026'!G371 -> 1216 | E11: 88 | F11: 55 | G11: =IFERROR(D11+E11-F11,"") -> 1249
C12: -100# | D12: ='Jan 2026'!G372 -> 871 | E12: 50 | F12: 36 | G12: =IFERROR(D12+E12-F12,"") -> 885
C13: 5mm | D13: ='Jan 2026'!G373 -> 995 | E13: 43 | F13: 35 | G13: =IFERROR(D13+E13-F13,"") -> 1003
C14: 1mm | D14: ='Jan 2026'!G374 -> 985 | E14: 41 | F14: 34 | G14: =IFERROR(D14+E14-F14,"") -> 992
C15: 2mm | D15: ='Jan 2026'!G375 -> 1150 | E15: 69 | F15: 47 | G15: =IFERROR(D15+E15-F15,"") -> 1172
C16: 3mm | D16: ='Jan 2026'!G376 -> 548 | E16: 49 | F16: 42 | G16: =IFERROR(D16+E16-F16,"") -> 555
C17: Dust/150# | D17: ='Jan 2026'!G377 -> 1529 | E17: 48 | F17: 32 | G17: =IFERROR(D17+E17-F17,"") -> 1545
A18: Total — 01 Feb 2026 | D18: =IFERROR(SUM(D7:D17),"") -> 11574 | E18: =IFERROR(SUM(E7:E17),"") -> 590 | F18: =IFERROR(SUM(F7:F17),"") -> 437 | G18: =IFERROR(SUM(G7:G17),"") -> 11727
A19: 46055 | B19: Mon | C19: 14/30# | D19: =G7 -> 1280 | E19: 117 | F19: 78 | G19: =IFERROR(D19+E19-F19,"") -> 1319
C20: 16/30# | D20: =G8 -> 920 | E20: 111 | F20: 89 | G20: =IFERROR(D20+E20-F20,"") -> 942
C21: 24/60# | D21: =G9 -> 1332 | E21: 149 | F21: 92 | G21: =IFERROR(D21+E21-F21,"") -> 1389
C22: 30/80# | D22: =G10 -> 794 | E22: 118 | F22: 107 | G22: =IFERROR(D22+E22-F22,"") -> 805
C23: 50/150# | D23: =G11 -> 1249 | E23: 141 | F23: 99 | G23: =IFERROR(D23+E23-F23,"") -> 1291
C24: -100# | D24: =G12 -> 885 | E24: 86 | F24: 74 | G24: =IFERROR(D24+E24-F24,"") -> 897
C25: 5mm | D25: =G13 -> 1003 | E25: 91 | F25: 72 | G25: =IFERROR(D25+E25-F25,"") -> 1022
C26: 1mm | D26: =G14 -> 992 | E26: 114 | F26: 76 | G26: =IFERROR(D26+E26-F26,"") -> 1030
C27: 2mm | D27: =G15 -> 1172 | E27: 105 | F27: 80 | G27: =IFERROR(D27+E27-F27,"") -> 1197
C28: 3mm | D28: =G16 -> 555 | E28: 105 | F28: 97 | G28: =IFERROR(D28+E28-F28,"") -> 563
C29: Dust/150# | D29: =G17 -> 1545 | E29: 151 | F29: 113 | G29: =IFERROR(D29+E29-F29,"") -> 1583
A30: Total — 02 Feb 2026 | D30: =IFERROR(SUM(D19:D29),"") -> 11727 | E30: =IFERROR(SUM(E19:E29),"") -> 1288 | F30: =IFERROR(SUM(F19:F29),"") -> 977 | G30: =IFERROR(SUM(G19:G29),"") -> 12038
A31: 46056 | B31: Tue | C31: 14/30# | D31: =G19 -> 1319 | E31: 90 | F31: 76 | G31: =IFERROR(D31+E31-F31,"") -> 1333
C32: 16/30# | D32: =G20 -> 942 | E32: 94 | F32: 82 | G32: =IFERROR(D32+E32-F32,"") -> 954
C33: 24/60# | D33: =G21 -> 1389 | E33: 98 | F33: 69 | G33: =IFERROR(D33+E33-F33,"") -> 1418
C34: 30/80# | D34: =G22 -> 805 | E34: 89 | F34: 70 | G34: =IFERROR(D34+E34-F34,"") -> 824
C35: 50/150# | D35: =G23 -> 1291 | E35: 121 | F35: 86 | G35: =IFERROR(D35+E35-F35,"") -> 1326
C36: -100# | D36: =G24 -> 897 | E36: 94 | F36: 81 | G36: =IFERROR(D36+E36-F36,"") -> 910
C37: 5mm | D37: =G25 -> 1022 | E37: 91 | F37: 69 | G37: =IFERROR(D37+E37-F37,"") -> 1044
C38: 1mm | D38: =G26 -> 1030 | E38: 116 | F38: 85 | G38: =IFERROR(D38+E38-F38,"") -> 1061
C39: 2mm | D39: =G27 -> 1197 | E39: 138 | F39: 92 | G39: =IFERROR(D39+E39-F39,"") -> 1243
C40: 3mm | D40: =G28 -> 563 | E40: 65 | F40: 57 | G40: =IFERROR(D40+E40-F40,"") -> 571
C41: Dust/150# | D41: =G29 -> 1583 | E41: 129 | F41: 97 | G41: =IFERROR(D41+E41-F41,"") -> 1615
A42: Total — 03 Feb 2026 | D42: =IFERROR(SUM(D31:D41),"") -> 12038 | E42: =IFERROR(SUM(E31:E41),"") -> 1125 | F42: =IFERROR(SUM(F31:F41),"") -> 864 | G42: =IFERROR(SUM(G31:G41),"") -> 12299
A43: 46057 | B43: Wed | C43: 14/30# | D43: =G31 -> 1333 | E43: 104 | F43: 86 | G43: =IFERROR(D43+E43-F43,"") -> 1351
...

Sheet Mar 2026
A1: PRECIOUS MINERALS
A5: DAILY PRODUCTION AND DISPATCH REGISTER — MARCH 2026
A6: Date | B6: Day | C6: Product | D6: Opening stock (in bags) | E6: Production (in bags) | F6: Sales (in bags) | G6: Closing stock (auto)
A7: 46082 | B7: Sun | C7: 14/30# | D7: ='Feb 2026'!G331 -> 1995 | E7: 75 | F7: 50 | G7: =IFERROR(D7+E7-F7,"") -> 2020
C8: 16/30# | D8: ='Feb 2026'!G332 -> 1428 | E8: 51 | F8: 38 | G8: =IFERROR(D8+E8-F8,"") -> 1441
C9: 24/60# | D9: ='Feb 2026'!G333 -> 2232 | E9: 39 | F9: 23 | G9: =IFERROR(D9+E9-F9,"") -> 2248
C10: 30/80# | D10: ='Feb 2026'!G334 -> 1171 | E10: 50 | F10: 39 | G10: =IFERROR(D10+E10-F10,"") -> 1182
C11: 50/150# | D11: ='Feb 2026'!G335 -> 2173 | E11: 78 | F11: 51 | G11: =IFERROR(D11+E11-F11,"") -> 2200
C12: -100# | D12: ='Feb 2026'!G336 -> 1300 | E12: 34 | F12: 25 | G12: =IFERROR(D12+E12-F12,"") -> 1309
C13: 5mm | D13: ='Feb 2026'!G337 -> 1426 | E13: 53 | F13: 47 | G13: =IFERROR(D13+E13-F13,"") -> 1432
C14: 1mm | D14: ='Feb 2026'!G338 -> 1602 | E14: 43 | F14: 30 | G14: =IFERROR(D14+E14-F14,"") -> 1615
C15: 2mm | D15: ='Feb 2026'!G339 -> 1840 | E15: 53 | F15: 41 | G15: =IFERROR(D15+E15-F15,"") -> 1852
C16: 3mm | D16: ='Feb 2026'!G340 -> 810 | E16: 27 | F16: 25 | G16: =IFERROR(D16+E16-F16,"") -> 812
C17: Dust/150# | D17: ='Feb 2026'!G341 -> 2440 | E17: 68 | F17: 54 | G17: =IFERROR(D17+E17-F17,"") -> 2454
A18: Total — 01 Mar 2026 | D18: =IFERROR(SUM(D7:D17),"") -> 18417 | E18: =IFERROR(SUM(E7:E17),"") -> 571 | F18: =IFERROR(SUM(F7:F17),"") -> 423 | G18: =IFERROR(SUM(G7:G17),"") -> 18565
A19: 46083 | B19: Mon | C19: 14/30# | D19: =G7 -> 2020 | E19: 149 | F19: 97 | G19: =IFERROR(D19+E19-F19,"") -> 2072
C20: 16/30# | D20: =G8 -> 1441 | E20: 92 | F20: 66 | G20: =IFERROR(D20+E20-F20,"") -> 1467
C21: 24/60# | D21: =G9 -> 2248 | E21: 123 | F21: 75 | G21: =IFERROR(D21+E21-F21,"") -> 2296
C22: 30/80# | D22: =G10 -> 1182 | E22: 94 | F22: 76 | G22: =IFERROR(D22+E22-F22,"") -> 1200
C23: 50/150# | D23: =G11 -> 2200 | E23: 105 | F23: 82 | G23: =IFERROR(D23+E23-F23,"") -> 2223
C24: -100# | D24: =G12 -> 1309 | E24: 107 | F24: 88 | G24: =IFERROR(D24+E24-F24,"") -> 1328
C25: 5mm | D25: =G13 -> 1432 | E25: 133 | F25: 111 | G25: =IFERROR(D25+E25-F25,"") -> 1454
C26: 1mm | D26: =G14 -> 1615 | E26: 67 | F26: 46 | G26: =IFERROR(D26+E26-F26,"") -> 1636
C27: 2mm | D27: =G15 -> 1852 | E27: 121 | F27: 85 | G27: =IFERROR(D27+E27-F27,"") -> 1888
C28: 3mm | D28: =G16 -> 812 | E28: 76 | F28: 72 | G28: =IFERROR(D28+E28-F28,"") -> 816
C29: Dust/150# | D29: =G17 -> 2454 | E29: 129 | F29: 97 | G29: =IFERROR(D29+E29-F29,"") -> 2486
A30: Total — 02 Mar 2026 | D30: =IFERROR(SUM(D19:D29),"") -> 18565 | E30: =IFERROR(SUM(E19:E29),"") -> 1196 | F30: =IFERROR(SUM(F19:F29),"") -> 895 | G30: =IFERROR(SUM(G19:G29),"") -> 18866
A31: 46084 | B31: Tue | C31: 14/30# | D31: =G19 -> 2072 | E31: 82 | F31: 58 | G31: =IFERROR(D31+E31-F31,"") -> 2096
C32: 16/30# | D32: =G20 -> 1467 | E32: 129 | F32: 98 | G32: =IFERROR(D32+E32-F32,"") -> 1498
C33: 24/60# | D33: =G21 -> 2296 | E33: 143 | F33: 104 | G33: =IFERROR(D33+E33-F33,"") -> 2335
C34: 30/80# | D34: =G22 -> 1200 | E34: 91 | F34: 69 | G34: =IFERROR(D34+E34-F34,"") -> 1222
C35: 50/150# | D35: =G23 -> 2223 | E35: 143 | F35: 97 | G35: =IFERROR(D35+E35-F35,"") -> 2269
C36: -100# | D36: =G24 -> 1328 | E36: 83 | F36: 57 | G36: =IFERROR(D36+E36-F36,"") -> 1354
C37: 5mm | D37: =G25 -> 1454 | E37: 100 | F37: 87 | G37: =IFERROR(D37+E37-F37,"") -> 1467
C38: 1mm | D38: =G26 -> 1636 | E38: 73 | F38: 62 | G38: =IFERROR(D38+E38-F38,"") -> 1647
C39: 2mm | D39: =G27 -> 1888 | E39: 131 | F39: 105 | G39: =IFERROR(D39+E39-F39,"") -> 1914
C40: 3mm | D40: =G28 -> 816 | E40: 77 | F40: 71 | G40: =IFERROR(D40+E40-F40,"") -> 822
C41: Dust/150# | D41: =G29 -> 2486 | E41: 136 | F41: 109 | G41: =IFERROR(D41+E41-F41,"") -> 2513
A42: Total — 03 Mar 2026 | D42: =IFERROR(SUM(D31:D41),"") -> 18866 | E42: =IFERROR(SUM(E31:E41),"") -> 1188 | F42: =IFERROR(SUM(F31:F41),"") -> 917 | G42: =IFERROR(SUM(G31:G41),"") -> 19137
A43: 46085 | B43: Wed | C43: 14/30# | D43: =G31 -> 2096 | E43: 121 | F43: 86 | G43: =IFERROR(D43+E43-F43,"") -> 2131
...

Sheet Apr 2026
A1: PRECIOUS MINERALS
A5: DAILY PRODUCTION AND DISPATCH REGISTER — APRIL 2026
A6: Date | B6: Day | C6: Product | D6: Opening stock (in bags) | E6: Production (in bags) | F6: Sales (in bags) | G6: Closing stock (auto)
A7: 46113 | B7: Wed | C7: 14/30# | D7: ='Mar 2026'!G367 -> 2759 | E7: 94 | F7: 61 | G7: =IFERROR(D7+E7-F7,"") -> 2792
C8: 16/30# | D8: ='Mar 2026'!G368 -> 2010 | E8: 117 | F8: 89 | G8: =IFERROR(D8+E8-F8,"") -> 2038
C9: 24/60# | D9: ='Mar 2026'!G369 -> 3174 | E9: 121 | F9: 79 | G9: =IFERROR(D9+E9-F9,"") -> 3216
C10: 30/80# | D10: ='Mar 2026'!G370 -> 1507 | E10: 68 | F10: 62 | G10: =IFERROR(D10+E10-F10,"") -> 1513
C11: 50/150# | D11: ='Mar 2026'!G371 -> 3148 | E11: 113 | F11: 91 | G11: =IFERROR(D11+E11-F11,"") -> 3170
C12: -100# | D12: ='Mar 2026'!G372 -> 1798 | E12: 97 | F12: 82 | G12: =IFERROR(D12+E12-F12,"") -> 1813
C13: 5mm | D13: ='Mar 2026'!G373 -> 1897 | E13: 86 | F13: 79 | G13: =IFERROR(D13+E13-F13,"") -> 1904
C14: 1mm | D14: ='Mar 2026'!G374 -> 2211 | E14: 92 | F14: 61 | G14: =IFERROR(D14+E14-F14,"") -> 2242
C15: 2mm | D15: ='Mar 2026'!G375 -> 2741 | E15: 88 | F15: 58 | G15: =IFERROR(D15+E15-F15,"") -> 2771
C16: 3mm | D16: ='Mar 2026'!G376 -> 1076 | E16: 68 | F16: 56 | G16: =IFERROR(D16+E16-F16,"") -> 1088
C17: Dust/150# | D17: ='Mar 2026'!G377 -> 3400 | E17: 159 | F17: 97 | G17: =IFERROR(D17+E17-F17,"") -> 3462
A18: Total — 01 Apr 2026 | D18: =IFERROR(SUM(D7:D17),"") -> 25721 | E18: =IFERROR(SUM(E7:E17),"") -> 1103 | F18: =IFERROR(SUM(F7:F17),"") -> 815 | G18: =IFERROR(SUM(G7:G17),"") -> 26009
A19: 46114 | B19: Thu | C19: 14/30# | D19: =G7 -> 2792 | E19: 80 | F19: 57 | G19: =IFERROR(D19+E19-F19,"") -> 2815
C20: 16/30# | D20: =G8 -> 2038 | E20: 114 | F20: 92 | G20: =IFERROR(D20+E20-F20,"") -> 2060
C21: 24/60# | D21: =G9 -> 3216 | E21: 133 | F21: 87 | G21: =IFERROR(D21+E21-F21,"") -> 3262
C22: 30/80# | D22: =G10 -> 1513 | E22: 69 | F22: 54 | G22: =IFERROR(D22+E22-F22,"") -> 1528
C23: 50/150# | D23: =G11 -> 3170 | E23: 143 | F23: 91 | G23: =IFERROR(D23+E23-F23,"") -> 3222
C24: -100# | D24: =G12 -> 1813 | E24: 55 | F24: 43 | G24: =IFERROR(D24+E24-F24,"") -> 1825
C25: 5mm | D25: =G13 -> 1904 | E25: 87 | F25: 73 | G25: =IFERROR(D25+E25-F25,"") -> 1918
C26: 1mm | D26: =G14 -> 2242 | E26: 119 | F26: 89 | G26: =IFERROR(D26+E26-F26,"") -> 2272
C27: 2mm | D27: =G15 -> 2771 | E27: 118 | F27: 76 | G27: =IFERROR(D27+E27-F27,"") -> 2813
C28: 3mm | D28: =G16 -> 1088 | E28: 101 | F28: 92 | G28: =IFERROR(D28+E28-F28,"") -> 1097
C29: Dust/150# | D29: =G17 -> 3462 | E29: 163 | F29: 106 | G29: =IFERROR(D29+E29-F29,"") -> 3519
A30: Total — 02 Apr 2026 | D30: =IFERROR(SUM(D19:D29),"") -> 26009 | E30: =IFERROR(SUM(E19:E29),"") -> 1182 | F30: =IFERROR(SUM(F19:F29),"") -> 860 | G30: =IFERROR(SUM(G19:G29),"") -> 26331
A31: 46115 | B31: Fri | C31: 14/30# | D31: =G19 -> 2815 | E31: 88 | F31: 58 | G31: =IFERROR(D31+E31-F31,"") -> 2845
C32: 16/30# | D32: =G20 -> 2060 | E32: 112 | F32: 85 | G32: =IFERROR(D32+E32-F32,"") -> 2087
C33: 24/60# | D33: =G21 -> 3262 | E33: 127 | F33: 78 | G33: =IFERROR(D33+E33-F33,"") -> 3311
C34: 30/80# | D34: =G22 -> 1528 | E34: 114 | F34: 92 | G34: =IFERROR(D34+E34-F34,"") -> 1550
C35: 50/150# | D35: =G23 -> 3222 | E35: 112 | F35: 81 | G35: =IFERROR(D35+E35-F35,"") -> 3253
C36: -100# | D36: =G24 -> 1825 | E36: 67 | F36: 52 | G36: =IFERROR(D36+E36-F36,"") -> 1840
C37: 5mm | D37: =G25 -> 1918 | E37: 121 | F37: 92 | G37: =IFERROR(D37+E37-F37,"") -> 1947
C38: 1mm | D38: =G26 -> 2272 | E38: 88 | F38: 69 | G38: =IFERROR(D38+E38-F38,"") -> 2291
C39: 2mm | D39: =G27 -> 2813 | E39: 111 | F39: 92 | G39: =IFERROR(D39+E39-F39,"") -> 2832
C40: 3mm | D40: =G28 -> 1097 | E40: 72 | F40: 67 | G40: =IFERROR(D40+E40-F40,"") -> 1102
C41: Dust/150# | D41: =G29 -> 3519 | E41: 104 | F41: 82 | G41: =IFERROR(D41+E41-F41,"") -> 3541
A42: Total — 03 Apr 2026 | D42: =IFERROR(SUM(D31:D41),"") -> 26331 | E42: =IFERROR(SUM(E31:E41),"") -> 1116 | F42: =IFERROR(SUM(F31:F41),"") -> 848 | G42: =IFERROR(SUM(G31:G41),"") -> 26599
A43: 46116 | B43: Sat | C43: 14/30# | D43: =G31 -> 2845 | E43: 67 | F43: 46 | G43: =IFERROR(D43+E43-F43,"") -> 2866
...

Sheet May 2026
A1: PRECIOUS MINERALS
A5: DAILY PRODUCTION AND DISPATCH REGISTER — MAY 2026
A6: Date | B6: Day | C6: Product | D6: Opening stock (in bags) | E6: Production (in bags) | F6: Sales (in bags) | G6: Closing stock (auto)
A7: 46143 | B7: Fri | C7: 14/30# | D7: ='Apr 2026'!G355 -> 3580 | E7: 87 | F7: 59 | G7: =IFERROR(D7+E7-F7,"") -> 3608
C8: 16/30# | D8: ='Apr 2026'!G356 -> 2608 | E8: 130 | F8: 115 | G8: =IFERROR(D8+E8-F8,"") -> 2623
C9: 24/60# | D9: ='Apr 2026'!G357 -> 4119 | E9: 116 | F9: 89 | G9: =IFERROR(D9+E9-F9,"") -> 4146
C10: 30/80# | D10: ='Apr 2026'!G358 -> 1845 | E10: 73 | F10: 62 | G10: =IFERROR(D10+E10-F10,"") -> 1856
C11: 50/150# | D11: ='Apr 2026'!G359 -> 4218 | E11: 110 | F11: 73 | G11: =IFERROR(D11+E11-F11,"") -> 4255
C12: -100# | D12: ='Apr 2026'!G360 -> 2222 | E12: 65 | F12: 46 | G12: =IFERROR(D12+E12-F12,"") -> 2241
C13: 5mm | D13: ='Apr 2026'!G361 -> 2404 | E13: 84 | F13: 65 | G13: =IFERROR(D13+E13-F13,"") -> 2423
C14: 1mm | D14: ='Apr 2026'!G362 -> 2778 | E14: 65 | F14: 48 | G14: =IFERROR(D14+E14-F14,"") -> 2795
C15: 2mm | D15: ='Apr 2026'!G363 -> 3535 | E15: 142 | F15: 112 | G15: =IFERROR(D15+E15-F15,"") -> 3565
C16: 3mm | D16: ='Apr 2026'!G364 -> 1348 | E16: 93 | F16: 87 | G16: =IFERROR(D16+E16-F16,"") -> 1354
C17: Dust/150# | D17: ='Apr 2026'!G365 -> 4514 | E17: 132 | F17: 81 | G17: =IFERROR(D17+E17-F17,"") -> 4565
A18: Total — 01 May 2026 | D18: =IFERROR(SUM(D7:D17),"") -> 33171 | E18: =IFERROR(SUM(E7:E17),"") -> 1097 | F18: =IFERROR(SUM(F7:F17),"") -> 837 | G18: =IFERROR(SUM(G7:G17),"") -> 33431
A19: 46144 | B19: Sat | C19: 14/30# | D19: =G7 -> 3608 | E19: 48 | F19: 40 | G19: =IFERROR(D19+E19-F19,"") -> 3616
C20: 16/30# | D20: =G8 -> 2623 | E20: 40 | F20: 34 | G20: =IFERROR(D20+E20-F20,"") -> 2629
C21: 24/60# | D21: =G9 -> 4146 | E21: 43 | F21: 33 | G21: =IFERROR(D21+E21-F21,"") -> 4156
C22: 30/80# | D22: =G10 -> 1856 | E22: 38 | F22: 30 | G22: =IFERROR(D22+E22-F22,"") -> 1864
C23: 50/150# | D23: =G11 -> 4255 | E23: 57 | F23: 37 | G23: =IFERROR(D23+E23-F23,"") -> 4275
C24: -100# | D24: =G12 -> 2241 | E24: 24 | F24: 16 | G24: =IFERROR(D24+E24-F24,"") -> 2249
C25: 5mm | D25: =G13 -> 2423 | E25: 40 | F25: 32 | G25: =IFERROR(D25+E25-F25,"") -> 2431
C26: 1mm | D26: =G14 -> 2795 | E26: 62 | F26: 44 | G26: =IFERROR(D26+E26-F26,"") -> 2813
C27: 2mm | D27: =G15 -> 3565 | E27: 62 | F27: 40 | G27: =IFERROR(D27+E27-F27,"") -> 3587
C28: 3mm | D28: =G16 -> 1354 | E28: 36 | F28: 32 | G28: =IFERROR(D28+E28-F28,"") -> 1358
C29: Dust/150# | D29: =G17 -> 4565 | E29: 82 | F29: 62 | G29: =IFERROR(D29+E29-F29,"") -> 4585
A30: Total — 02 May 2026 | D30: =IFERROR(SUM(D19:D29),"") -> 33431 | E30: =IFERROR(SUM(E19:E29),"") -> 532 | F30: =IFERROR(SUM(F19:F29),"") -> 400 | G30: =IFERROR(SUM(G19:G29),"") -> 33563
A31: 46145 | B31: Sun | C31: 14/30# | D31: =G19 -> 3616 | E31: 59 | F31: 49 | G31: =IFERROR(D31+E31-F31,"") -> 3626
C32: 16/30# | D32: =G20 -> 2629 | E32: 48 | F32: 42 | G32: =IFERROR(D32+E32-F32,"") -> 2635
C33: 24/60# | D33: =G21 -> 4156 | E33: 52 | F33: 31 | G33: =IFERROR(D33+E33-F33,"") -> 4177
C34: 30/80# | D34: =G22 -> 1864 | E34: 29 | F34: 22 | G34: =IFERROR(D34+E34-F34,"") -> 1871
C35: 50/150# | D35: =G23 -> 4275 | E35: 83 | F35: 51 | G35: =IFERROR(D35+E35-F35,"") -> 4307
C36: -100# | D36: =G24 -> 2249 | E36: 37 | F36: 25 | G36: =IFERROR(D36+E36-F36,"") -> 2261
C37: 5mm | D37: =G25 -> 2431 | E37: 41 | F37: 36 | G37: =IFERROR(D37+E37-F37,"") -> 2436
C38: 1mm | D38: =G26 -> 2813 | E38: 59 | F38: 48 | G38: =IFERROR(D38+E38-F38,"") -> 2824
C39: 2mm | D39: =G27 -> 3587 | E39: 62 | F39: 43 | G39: =IFERROR(D39+E39-F39,"") -> 3606
C40: 3mm | D40: =G28 -> 1358 | E40: 27 | F40: 25 | G40: =IFERROR(D40+E40-F40,"") -> 1360
C41: Dust/150# | D41: =G29 -> 4585 | E41: 65 | F41: 49 | G41: =IFERROR(D41+E41-F41,"") -> 4601
A42: Total — 03 May 2026 | D42: =IFERROR(SUM(D31:D41),"") -> 33563 | E42: =IFERROR(SUM(E31:E41),"") -> 562 | F42: =IFERROR(SUM(F31:F41),"") -> 421 | G42: =IFERROR(SUM(G31:G41),"") -> 33704
A43: 46146 | B43: Mon | C43: 14/30# | D43: =G31 -> 3626 | E43: 93 | F43: 65 | G43: =IFERROR(D43+E43-F43,"") -> 3654
...

Sheet Jun 2026
A1: PRECIOUS MINERALS
A5: DAILY PRODUCTION AND DISPATCH REGISTER — JUNE 2026
A6: Date | B6: Day | C6: Product | D6: Opening stock (in bags) | E6: Production (in bags) | F6: Sales (in bags) | G6: Closing stock (auto)
A7: 46174 | B7: Mon | C7: 14/30# | D7: ='May 2026'!G367 -> 4322 | E7: 110 | F7: 83 | G7: =IFERROR(D7+E7-F7,"") -> 4349
C8: 16/30# | D8: ='May 2026'!G368 -> 3122 | E8: 75 | F8: 63 | G8: =IFERROR(D8+E8-F8,"") -> 3134
C9: 24/60# | D9: ='May 2026'!G369 -> 5094 | E9: 118 | F9: 70 | G9: =IFERROR(D9+E9-F9,"") -> 5142
C10: 30/80# | D10: ='May 2026'!G370 -> 2168 | E10: 80 | F10: 63 | G10: =IFERROR(D10+E10-F10,"") -> 2185
C11: 50/150# | D11: ='May 2026'!G371 -> 5259 | E11: 142 | F11: 113 | G11: =IFERROR(D11+E11-F11,"") -> 5288
C12: -100# | D12: ='May 2026'!G372 -> 2708 | E12: 59 | F12: 42 | G12: =IFERROR(D12+E12-F12,"") -> 2725
C13: 5mm | D13: ='May 2026'!G373 -> 2909 | E13: 79 | F13: 65 | G13: =IFERROR(D13+E13-F13,"") -> 2923
C14: 1mm | D14: ='May 2026'!G374 -> 3386 | E14: 123 | F14: 96 | G14: =IFERROR(D14+E14-F14,"") -> 3413
C15: 2mm | D15: ='May 2026'!G375 -> 4369 | E15: 102 | F15: 80 | G15: =IFERROR(D15+E15-F15,"") -> 4391
C16: 3mm | D16: ='May 2026'!G376 -> 1617 | E16: 83 | F16: 64 | G16: =IFERROR(D16+E16-F16,"") -> 1636
C17: Dust/150# | D17: ='May 2026'!G377 -> 5454 | E17: 105 | F17: 64 | G17: =IFERROR(D17+E17-F17,"") -> 5495
A18: Total — 01 Jun 2026 | D18: =IFERROR(SUM(D7:D17),"") -> 40408 | E18: =IFERROR(SUM(E7:E17),"") -> 1076 | F18: =IFERROR(SUM(F7:F17),"") -> 803 | G18: =IFERROR(SUM(G7:G17),"") -> 40681
A19: 46175 | B19: Tue | C19: 14/30# | D19: =G7 -> 4349 | E19: 94 | F19: 70 | G19: =IFERROR(D19+E19-F19,"") -> 4373
C20: 16/30# | D20: =G8 -> 3134 | E20: 85 | F20: 68 | G20: =IFERROR(D20+E20-F20,"") -> 3151
C21: 24/60# | D21: =G9 -> 5142 | E21: 105 | F21: 64 | G21: =IFERROR(D21+E21-F21,"") -> 5183
C22: 30/80# | D22: =G10 -> 2185 | E22: 75 | F22: 69 | G22: =IFERROR(D22+E22-F22,"") -> 2191
C23: 50/150# | D23: =G11 -> 5288 | E23: 179 | F23: 139 | G23: =IFERROR(D23+E23-F23,"") -> 5328
C24: -100# | D24: =G12 -> 2725 | E24: 54 | F24: 37 | G24: =IFERROR(D24+E24-F24,"") -> 2742
C25: 5mm | D25: =G13 -> 2923 | E25: 138 | F25: 118 | G25: =IFERROR(D25+E25-F25,"") -> 2943
C26: 1mm | D26: =G14 -> 3413 | E26: 99 | F26: 65 | G26: =IFERROR(D26+E26-F26,"") -> 3447
C27: 2mm | D27: =G15 -> 4391 | E27: 150 | F27: 114 | G27: =IFERROR(D27+E27-F27,"") -> 4427
C28: 3mm | D28: =G16 -> 1636 | E28: 70 | F28: 65 | G28: =IFERROR(D28+E28-F28,"") -> 1641
C29: Dust/150# | D29: =G17 -> 5495 | E29: 113 | F29: 77 | G29: =IFERROR(D29+E29-F29,"") -> 5531
A30: Total — 02 Jun 2026 | D30: =IFERROR(SUM(D19:D29),"") -> 40681 | E30: =IFERROR(SUM(E19:E29),"") -> 1162 | F30: =IFERROR(SUM(F19:F29),"") -> 886 | G30: =IFERROR(SUM(G19:G29),"") -> 40957
A31: 46176 | B31: Wed | C31: 14/30# | D31: =G19 -> 4373 | E31: 90 | F31: 74 | G31: =IFERROR(D31+E31-F31,"") -> 4389
C32: 16/30# | D32: =G20 -> 3151 | E32: 93 | F32: 67 | G32: =IFERROR(D32+E32-F32,"") -> 3177
C33: 24/60# | D33: =G21 -> 5183 | E33: 157 | F33: 95 | G33: =IFERROR(D33+E33-F33,"") -> 5245
C34: 30/80# | D34: =G22 -> 2191 | E34: 84 | F34: 78 | G34: =IFERROR(D34+E34-F34,"") -> 2197
C35: 50/150# | D35: =G23 -> 5328 | E35: 105 | F35: 85 | G35: =IFERROR(D35+E35-F35,"") -> 5348
C36: -100# | D36: =G24 -> 2742 | E36: 74 | F36: 61 | G36: =IFERROR(D36+E36-F36,"") -> 2755
C37: 5mm | D37: =G25 -> 2943 | E37: 107 | F37: 77 | G37: =IFERROR(D37+E37-F37,"") -> 2973
C38: 1mm | D38: =G26 -> 3447 | E38: 87 | F38: 59 | G38: =IFERROR(D38+E38-F38,"") -> 3475
C39: 2mm | D39: =G27 -> 4427 | E39: 129 | F39: 89 | G39: =IFERROR(D39+E39-F39,"") -> 4467
C40: 3mm | D40: =G28 -> 1641 | E40: 101 | F40: 98 | G40: =IFERROR(D40+E40-F40,"") -> 1644
C41: Dust/150# | D41: =G29 -> 5531 | E41: 108 | F41: 83 | G41: =IFERROR(D41+E41-F41,"") -> 5556
A42: Total — 03 Jun 2026 | D42: =IFERROR(SUM(D31:D41),"") -> 40957 | E42: =IFERROR(SUM(E31:E41),"") -> 1135 | F42: =IFERROR(SUM(F31:F41),"") -> 866 | G42: =IFERROR(SUM(G31:G41),"") -> 41226
A43: 46177 | B43: Thu | C43: 14/30# | D43: =G31 -> 4389 | E43: 139 | F43: 112 | G43: =IFERROR(D43+E43-F43,"") -> 4416
...
